Workbook

Sheet WK21
B2: ALLEEN GEKLEURDE LETTERS EN CIJFERS INGEVEN!
P4: Overige
D5: Dagen | E5: Uren | F5: VAK | G5: ZIEK | H5: RV | I5: KV/C | J5: FD | L5: Enkel | M5: Totaal | O5: Bedrag km/ | P5: Extra | Q5: Totaal
C6: Contract | D6: ge- | E6: ge- | F6: Op- | G6: Op- | H6: Op- | I6: Door | J6: Door | K6: Netto | L6: Km woon- | M6: Km werk- | N6: Totaal | O6: brandstof | P6: Declaratie | Q6: Netto
B7: Werknemer | C7: Uren | D7: werkt | E7: werkt | F7: name | G7: name | H7: name | I7: bet. | J7: bet. | K7: bedrag | L7: werk pd | M7: werk | N7: Km | O7: bedrag | P7: vergoeding | Q7: Voorschot | R7: Opmerking | S7: Actueel project en KM's enkele reis
B8: =Periode!B8 -> Ruben Hellemons | C8: =Periode!G8 -> 124 (4wk) | D8: 4 | E8: 32 | F8: 8 | K8: =(Periode!BB8*E8/40)+((F8+H8+I8)*Periode!BD8/40)+(J8*Periode!BF8/40)+(G8*Periode!BE8/40) -> 717.44036 | Q8: =K8+O8+P8 -> 717.44036 | R8: MaV8 | S8: 1-VSV-81 met verklaring
B12: =Periode!B12 -> Andre Sintenie | C12: =Periode!G12 -> 32 (4wk) | D12: 2 | E12: 16 | G12: =8*0.95 -> 7.6 | K12: =(Periode!BB12*E12/40)+((F12+H12+I12)*Periode!BD12/40)+(J12*Periode!BF12/40)+(G12*Periode!BE12/40) -> 383.7948 | Q12: =K12+O12+P12 -> 383.7948 | R12: MaEZ DiZ8 95% VrE8 | S12: VV-204-L met verklaring
C13: =Periode!H13 -> 0 | Q13: =K13+O13+P13 -> 0
R14: 4 wekelijkse betaling
B15: =Periode!B15 -> Dennis Aarts | C15: =Periode!G15 -> 0 | K15: =(Periode!BB15*E15/40)+((F15+H15+I15)*Periode!BD15/40)+(J15*Periode!BF15/40)+(G15*Periode!BE15/40) -> 0 | Q15: =K15+O15+P15 -> 0 | R15: E40 | S15: 98-XH-DP Bijtelling
B17: =Periode!B17 -> Kay Sanders | L17: 69
K20: =(Periode!BB20*E20/40)+((F20+H20+I20)*Periode!BD20/40)+(J20*Periode!BF20/40)+(G20*Periode!BE20/40) -> 0 | Q20: =K20+O20+P20 -> 0
B23: =Periode!B23 -> Frank Stouthart | C23: =Periode!G23 -> 32 (4wk) | D23: 4 | E23: 32 | F23: 8 | K23: =(Periode!BB23*E23/40)+((F23+H23+I23)*Periode!BD23/40)+(J23*Periode!BF23/40)+(G23*Periode!BE23/40) -> 701.67964 | L23: 34 | N23: =(L23*D23*2)+M23 -> 272 | O23: =((L23*2*D23)+M23)*0.28 -> 76.16 | Q23: =K23+O23+P23 -> 777.83964 | R23: VrV8 | S23: Vredespaleis Den Haag 34km, Lantaarnvenster R'dam 29km, Kralingseweg 179 R'dam 22 km (schrijft zelf 23km); Voorstraat Voorburg 38 km (schrijft 37km); Petrus Pauluskerk Leidschendam 31km (schrijft 33km); Kerkstraat Voorburg 31km (schrijft 33k); Koninginnegracht Den Haag 33km (schrijft 27 als hij stukje meerijdt); Tiber, den Haag 27km; Rokin 112, amsterdam 71 km (schrijft 70km); Concertgebouw 73km;
B26: =Periode!B26 -> Roy Rubeling | C26: =Periode!G26 -> 0 | D26: 3 | E26: 24 | K26: =(Periode!BB26*E26/40)+((F26+H26+I26)*Periode!BD26/40)+(J26*Periode!BF26/40)+(G26*Periode!BE26/40) -> 450 | L26: 61 | M26: =20+20+20 -> 60 | N26: =(L26*D26*2)+M26 -> 426 | O26: =((L26*2*D26)+M26)*0.28 -> 119.28 | Q26: =K26+O26+P26 -> 569.28 | R26: MaE8 VrWAZO | S26: Akoestische maatregelen Schiphol 61km
R27: Week 19 dubbel betaald € -569,28 van de € 754,00
T31: €
B33: =Periode!B33 -> Marco Govers | C33: =Periode!G33 -> 32 (4wk) | D33: 5 | E33: 40 | K33: =(Periode!BB33*E33/40)+((F33+H33+I33)*Periode!BD33/40)+(J33*Periode!BF33/40)+(G33*Periode!BE33/40) -> 775.21 | L33: 39 | N33: =(L33*D33*2)+M33 -> 390 | O33: =((L33*2*D33)+M33)*0.28 -> 109.2 | Q33: =K33+O33+P33 -> 884.41 | S33: Het Groot Kwartier 39km (schrijft 40)
B35: =Periode!B35 -> Onno de Vries | C35: =Periode!G35 -> 124 (4wk) | D35: 5 | E35: 40 | K35: =(Periode!BB35*E35/40)+((F35+H35+I35)*Periode!BD35/40)+(J35*Periode!BF35/40)+(G35*Periode!BE35/40) -> 633.355 | L35: 10 | N35: =(L35*D35*2)+M35 -> 100 | O35: =((L35*2*D35)+M35)*0.28 -> 28 | Q35: =K35+O35+P35 -> 661.355 | S35: LP4 10 km (schrijft 11km)
B39: =Periode!B39 -> Jan Levering | C39: =Periode!G39 -> 32 (4wk) | K39: =(Periode!BB39*E39/40)+((F39+H39+I39)*Periode!BD39/40)+(J39*Periode!BF39/40)+(G39*Periode!BE39/40) -> 0 | P39: 143.37 | Q39: =K39+O39+P39 -> 143.37 | R39: Aanvulling ZW € 143,37 | S39: Verklaring 1-VXV-55
B42: =Periode!B42 -> Alex van der Laan | C42: =Periode!G42 -> 32 (wk) | D42: 5 | E42: 36 | K42: =(Periode!BB42*E42/40)+((F42+H42+I42)*Periode!BD42/40)+(J42*Periode!BF42/40)+(G42*Periode!BE42/40) -> 606.375 | Q42: =K42+O42+P42 -> 606.375 | R42: VrE4 | S42: Bijtelling 36-GNP-4
R43: Betalen Bewind:
R44: =K46 -> 463.94531 | S44: Bijtelling 78-RJ-BP
R45: Betalen Shafieq: | S45: Onkosten betalen op rekening Shafieq: NL65 ABNA 0128 6728 97
B46: =Periode!B46 -> Shafieq Asgarali | C46: =Periode!G46 -> 32 (4wk) | D46: 5 | E46: 37.5 | K46: =(Periode!BB46*E46/40)+((F46+H46+I46)*Periode!BD46/40)+(J46*Periode!BF46/40)+(G46*Periode!BE46/40) -> 463.94531 | P46: =(D46*Periode!AY46) -> 58.25 | Q46: =K46+O46+P46 -> 522.19531 | R46: =P46 -> 58.25 | S46: Loon betalen onder bewindvoering: NL93 ABNA 0128 6727 81
R47: Ma t/m VrZ7,4 - Restant loonbeslag:
B48: =Periode!B48 -> Sander van den Hoek | C48: =Periode!G48 -> 32 (wk) | G48: =(5*7.4)*0.9 -> 33.3 | K48: =(Periode!BB48*E48/40)+((F48+H48+I48)*Periode!BD48/40)+(J48*Periode!BF48/40)+(G48*Periode!BE48/40) -> 478.62506 | L48: 5 | N48: =(L48*D48*2)+M48 -> 0 | O48: =((L48*2*D48)+M48)*0.23 -> 0 | P48: =(D48*Periode!AY48) -> 0 | Q48: =K48+O48+P48+P49 -> 478.62506 | R48: =(1301*12/13)-K48 -> 722.29801 | S48: St. Martinuskerk Voorburg 11 km
R49: Betalen Sander: | S49: Loonbeslag Belastindienst NL89 INGB 000 000 4820
C50: =Periode!G50 -> 0 | R50: =Q48 -> 478.62506 | S50: t.n.v. S. van den Hoek 1735.64.781
B53: =Periode!B53 -> Ronald van Maanen | C53: =Periode!G53 -> 32 (4wk) | D53: 5 | E53: 38 | K53: =(Periode!BB53*E53/40)+((F53+H53+I53)*Periode!BD53/40)+(J53*Periode!BF53/40)+(G53*Periode!BE53/40) -> 696.5875 | L53: 49 | N53: =(L53*D53*2)+M53 -> 490 | O53: =((L53*2*D53)+M53)*0.28 -> 137.2 | Q53: =K53+O53+P53 -> 833.7875 | R53: VrE2 | S53: Nijmegen gemiddelde heen/terug 49km
C54: =Periode!H75 -> 0
C55: =Periode!H76 -> 0
B57: =Periode!B57 -> Erik Visser | C57: =Periode!G57 -> 32 (4wk) | D57: 5 | E57: 35 | K57: =(Periode!BB57*E57/40)+((F57+H57+I57)*Periode!BD57/40)+(J57*Periode!BF57/40)+(G57*Periode!BE57/40) -> 490.385 | L57: 14 | M57: =82+30+64+30+72 -> 278 | N57: =(L57*D57*2)+M57 -> 418 | O57: =((L57*2*D57))*0.23+(M57*0.28) -> 110.04 | Q57: =K57+O57+P57 -> 600.425 | R57: DiE5 | S57: Janssen de Jong OnderhoudPlus 14km
S58: wer-werk km € 0,28 (€ 0,32 naar de klant)
C59: =Periode!G59 -> 0 | K59: =(Periode!BB59*E59/40)+((F59+H59+I59)*Periode!BD59/40)+(J59*Periode!BF59/40)+(G59*Periode!BE59/40) -> 0 | Q59: =K59+O59+P59 -> 0
R60: Betalen Bewind:
R61: =K63 -> 463.94531
R62: Betalen Youri:
B63: =Periode!B63 -> Youri Nouwens | C63: =Periode!G63 -> 32 (4wk) | E63: 37.5 | K63: =(Periode!BB63*E63/40)+((F63+H63+I63)*Periode!BD63/40)+(J63*Periode!BF63/40)+(G63*Periode!BE63/40) -> 463.94531 | P63: =(D63*Periode!AY63) -> 0 | Q63: =K63+O63+P63 -> 463.94531 | R63: =P63 -> 0 | S63: Bijtelling 54-GDT-8
R64: Leegloop | S64: Loon overmaken naar Bewindvoerder: NL20 ABNA 0830 2655 89 - De Maas dienstverlening
S65: Onkosten overmaken naar Youri: NL21 INGB 0799 0333 59
...

Sheet WK22
B2: ALLEEN GEKLEURDE LETTERS EN CIJFERS INGEVEN!
P4: Overige
D5: Dagen | E5: Uren | F5: VAK | G5: ZIEK | H5: RV | I5: KV/C | J5: FD | L5: Enkel | M5: Totaal | O5: Bedrag km/ | P5: Extra | Q5: Totaal
C6: Contract | D6: ge- | E6: ge- | F6: Op- | G6: Op- | H6: Op- | I6: Door | J6: Door | K6: Netto | L6: Km woon- | M6: Km werk- | N6: Totaal | O6: brandstof | P6: Declaratie/ | Q6: Netto
B7: Werknemer | C7: Uren | D7: werkt | E7: werkt | F7: name | G7: name | H7: name | I7: bet. | J7: bet. | K7: bedrag | L7: werk pd | M7: werk pd | N7: Km | O7: bedrag | P7: vergoeding | Q7: Voorschot | R7: Opmerking | S7: Actueel project en KM's enkele reis
B8: =Periode!B8 -> Ruben Hellemons | C8: =Periode!G8 -> 124 (4wk) | D8: 4 | E8: 32 | J8: 8 | K8: =(Periode!BB8*E8/40)+((F8+H8+I8)*Periode!BD8/40)+(J8*Periode!BF8/40)+(G8*Periode!BE8/40) -> 717.44036 | Q8: =K8+O8+P8 -> 717.44036 | R8: MaF8 | S8: 1-VSV-81 met verklaring
B12: =Periode!B12 -> Andre Sintenie | C12: =Periode!G12 -> 32 (4wk) | D12: 3 | E12: 24 | J12: 8 | K12: =(Periode!BB12*E12/40)+((F12+H12+I12)*Periode!BD12/40)+(J12*Periode!BF12/40)+(G12*Periode!BE12/40) -> 521.23368 | Q12: =K12+O12+P12 -> 521.23368 | R12: MaF8 VrE8 | S12: VV-204-L met verklaring
B13: =Periode!B13 -> 0 | C13: =Periode!H13 -> 0 | Q13: =K13+O13+P13 -> 0
B15: =Periode!B15 -> Dennis Aarts | C15: =Periode!G15 -> 0 | J15: 8 | K15: =(Periode!BB15*E15/40)+((F15+H15+I15)*Periode!BD15/40)+(J15*Periode!BF15/40)+(G15*Periode!BE15/40) -> 137.08728 | Q15: =K15+O15+P15 -> 137.08728 | R15: 4 wekelijkse betaling | S15: 98-XH-DP Bijtelling
R16: MaF8 E32
B17: =Periode!B17 -> Kay Sanders
K20: =(Periode!BB20*E20/40)+((F20+H20+I20)*Periode!BD20/40)+(J20*Periode!BF20/40)+(G20*Periode!BE20/40) -> 0 | Q20: =K20+O20+P20 -> 0
B23: =Periode!B23 -> Frank Stouthart | C23: =Periode!G23 -> 32 (4wk) | D23: 4 | E23: 30 | J23: 8 | K23: =(Periode!BB23*E23/40)+((F23+H23+I23)*Periode!BD23/40)+(J23*Periode!BF23/40)+(G23*Periode!BE23/40) -> 666.36564 | L23: 34 | M23: =-272+(6*34)+(2*37) -> 6 | N23: =(L23*D23*2)+M23 -> 278 | O23: =((L23*2*D23)+M23)*0.28 -> 77.84 | Q23: =K23+O23+P23 -> 744.20564 | R23: MaF8 | S23: Vredespaleis Den Haag 34km, Lantaarnvenster R'dam 29km, Kralingseweg 179 R'dam 22 km (schrijft zelf 23km); Voorstraat Voorburg 38 km (schrijft 37km); Petrus Pauluskerk Leidschendam 31km (schrijft 33km); Kerkstraat Voorburg 31km (schrijft 33k); Koninginnegracht Den Haag 33km (schrijft 27 als hij stukje meerijdt); Tiber, den Haag 27km; Rokin 112, amsterdam 71 km (schrijft 70km); Concertgebouw 73km;
B26: =Periode!B26 -> Roy Rubeling | C26: =Periode!G26 -> 0 | D26: 3 | E26: 24 | J26: 8 | K26: =(Periode!BB26*E26/40)+((F26+H26+I26)*Periode!BD26/40)+(J26*Periode!BF26/40)+(G26*Periode!BE26/40) -> 596.2626 | L26: 61 | M26: =20+20+20 -> 60 | N26: =(L26*D26*2)+M26 -> 426 | O26: =((L26*2*D26)+M26)*0.28 -> 119.28 | Q26: =K26+O26+P26 -> 715.5426 | R26: VrWAZO | S26: Akoestische maatregelen Schiphol 61km
R27: Week 19 dubbel betaald restant van € 754,00
T31: €
B33: =Periode!B33 -> Marco Govers | C33: =Periode!G33 -> 32 (4wk) | D33: 4 | E33: 30 | I33: 2 | J33: 8 | K33: =(Periode!BB33*E33/40)+((F33+H33+I33)*Periode!BD33/40)+(J33*Periode!BF33/40)+(G33*Periode!BE33/40) -> 770.47523 | L33: 39 | N33: =(L33*D33*2)+M33 -> 312 | O33: =((L33*2*D33)+M33)*0.28 -> 87.36 | Q33: =K33+O33+P33 -> 857.83523 | R33: MaF8 VrKV2 | S33: Het Groot Kwartier 39km (schrijft 40)
B35: =Periode!B35 -> Onno de Vries | C35: =Periode!G35 -> 124 (4wk) | D35: 4 | E35: 32 | J35: 8 | K35: =(Periode!BB35*E35/40)+((F35+H35+I35)*Periode!BD35/40)+(J35*Periode!BF35/40)+(G35*Periode!BE35/40) -> 629.85089 | L35: 10 | N35: =(L35*D35*2)+M35 -> 80 | O35: =((L35*2*D35)+M35)*0.28 -> 22.4 | Q35: =K35+O35+P35 -> 652.25089 | R35: MaF8 | S35: LP4 10 km (schrijft 11km)
B39: =Periode!B39 -> Jan Levering | C39: =Periode!G39 -> 32 (4wk) | K39: =(Periode!BB39*E39/40)+((F39+H39+I39)*Periode!BD39/40)+(J39*Periode!BF39/40)+(G39*Periode!BE39/40) -> 0 | P39: 143.37 | Q39: =K39+O39+P39 -> 143.37 | R39: Aanvulling ZW € 143,37 | S39: Verklaring 1-VXV-55
B42: =Periode!B42 -> Alex van der Laan | C42: =Periode!G42 -> 32 (wk) | F42: 24 | I42: 8 | J42: 8 | K42: =(Periode!BB42*E42/40)+((F42+H42+I42)*Periode!BD42/40)+(J42*Periode!BF42/40)+(G42*Periode!BE42/40) -> 655.8255 | Q42: =K42+O42+P42 -> 655.8255 | R42: MaF8 DiKV8 V24 | S42: Bijtelling 36-GNP-4
R43: Betalen Bewind:
R44: =K46 -> 463.94531 | S44: Bijtelling 78-RJ-BP
R45: MaF7,5 - Betalen Shafieq: | S45: Onkosten betalen op rekening Shafieq: NL65 ABNA 0128 6728 97
B46: =Periode!B46 -> Shafieq Asgarali | C46: =Periode!G46 -> 32 (4wk) | D46: 4 | E46: 30 | J46: 7.5 | K46: =(Periode!BB46*E46/40)+((F46+H46+I46)*Periode!BD46/40)+(J46*Periode!BF46/40)+(G46*Periode!BE46/40) -> 463.94531 | P46: =(D46*Periode!AY46) -> 46.6 | Q46: =K46+O46+P46 -> 510.54531 | R46: =P46 -> 46.6 | S46: Loon betalen onder bewindvoering: NL93 ABNA 0128 6727 81
R47: Restant loonbeslag:
B48: =Periode!B48 -> Sander van den Hoek | C48: =Periode!G48 -> 32 (wk) | G48: =(5*7.4)*0.9 -> 33.3 | K48: =(Periode!BB48*E48/40)+((F48+H48+I48)*Periode!BD48/40)+(J48*Periode!BF48/40)+(G48*Periode!BE48/40) -> 478.62506 | L48: 28 | N48: =(L48*D48*2)+M48 -> 0 | O48: =((L48*2*D48)+M48)*0.25 -> 0 | P48: =(D48*Periode!AY48) -> 0 | Q48: =K48+O48+P48+P49 -> 478.62506 | R48: ='WK21'!R48-K48 -> 243.67295 | S48: St. Martinuskerk Voorburg 11 km
R49: Z100% - Betalen Sander: | S49: Loonbeslag Belastindienst NL89 INGB 000 000 4820
B50: =Periode!B50 -> 0 | C50: =Periode!G50 -> 0 | R50: =Q48 -> 478.62506 | S50: t.n.v. S. van den Hoek 1735.64.781
B53: =Periode!B53 -> Ronald van Maanen | C53: =Periode!G53 -> 32 (4wk) | D53: 4 | E53: 32 | J53: 8 | K53: =(Periode!BB53*E53/40)+((F53+H53+I53)*Periode!BD53/40)+(J53*Periode!BF53/40)+(G53*Periode!BE53/40) -> 728.5957 | L53: 49 | N53: =(L53*D53*2)+M53 -> 392 | O53: =((L53*2*D53)+M53)*0.28 -> 109.76 | Q53: =K53+O53+P53 -> 838.3557 | R53: MaF8 | S53: Nijmegen gemiddelde heen/terug 49km
B54: =Periode!B75 -> 0 | C54: =Periode!H75 -> 0
B55: =Periode!B76 -> 0 | C55: =Periode!H76 -> 0
B57: =Periode!B57 -> Erik Visser | C57: =Periode!G57 -> 32 (4wk) | D57: 4 | E57: 29.5 | J57: 8 | K57: =(Periode!BB57*E57/40)+((F57+H57+I57)*Periode!BD57/40)+(J57*Periode!BF57/40)+(G57*Periode!BE57/40) -> 522.23242 | L57: 14 | M57: =70+70+70+30 -> 240 | N57: =(L57*D57*2)+M57 -> 352 | O57: =((L57*2*D57))*0.25+(M57*0.28) -> 95.2 | P57: =(140*0.02)+37.38 -> 40.18 | Q57: =K57+O57+P57 -> 657.61242 | R57: MaF8 DiE2,5 | S57: Janssen de Jong OnderhoudPlus 14km
R58: Declaratie materiaal €37,38 | S58: wer-werk km € 0,28 (€ 0,32 naar de klant)
B59: =Periode!B59 -> 0 | C59: =Periode!G59 -> 0 | K59: =(Periode!BB59*E59/40)+((F59+H59+I59)*Periode!BD59/40)+(J59*Periode!BF59/40)+(G59*Periode!BE59/40) -> 0 | Q59: =K59+O59+P59 -> 0
R60: Betalen Bewind:
B61: =Periode!B61 -> 0 | R61: =K63 -> 463.94531
B62: =Periode!B62 -> 0 | R62: Betalen Youri:
B63: =Periode!B63 -> Youri Nouwens | C63: =Periode!G63 -> 32 (4wk) | E63: 37.5 | K63: =(Periode!BB63*E63/40)+((F63+H63+I63)*Periode!BD63/40)+(J63*Periode!BF63/40)+(G63*Periode!BE63/40) -> 463.94531 | P63: =(D63*Periode!AY63) -> 0 | Q63: =K63+O63+P63 -> 463.94531 | R63: =P63 -> 0 | S63: Bijtelling 54-GDT-8
B64: =Periode!B64 -> 0 | R64: Leegloop | S64: Loon overmaken naar Bewindvoerder: NL20 ABNA 0830 2655 89 - De Maas dienstverlening
S65: Onkosten overmaken naar Youri: NL21 INGB 0799 0333 59
...

Sheet WK23
B2: ALLEEN GEKLEURDE LETTERS EN CIJFERS INGEVEN!
P4: Overige
D5: Dagen | E5: Uren | F5: VAK | G5: ZIEK | H5: RV | I5: KV/C | J5: FD | L5: Enkel | M5: Totaal | O5: Bedrag km/ | P5: Extra | Q5: Totaal
C6: Contract | D6: ge- | E6: ge- | F6: Op- | G6: Op- | H6: Op- | I6: Door | J6: Door | K6: Netto | L6: Km woon- | M6: Km werk- | N6: Totaal | O6: brandstof | P6: Declaratie | Q6: Netto
B7: Werknemer | C7: Uren | D7: werkt | E7: werkt | F7: name | G7: name | H7: name | I7: bet. | J7: bet. | K7: bedrag | L7: werk pd | M7: werk pd | N7: Km | O7: bedrag | P7: vergoeding | Q7: Voorschot | R7: Opmerking | S7: Actueel project en KM's enkele reis
B8: =Periode!B8 -> Ruben Hellemons | C8: =Periode!G8 -> 124 (4wk) | D8: 5 | E8: 40 | K8: =(Periode!BB8*E8/40)+((F8+H8+I8)*Periode!BD8/40)+(J8*Periode!BF8/40)+(G8*Periode!BE8/40) -> 721.12 | Q8: =K8+O8+P8 -> 721.12 | S8: 1-VSV-81 met verklaring
B12: =Periode!B12 -> Andre Sintenie | C12: =Periode!G12 -> 32 (4wk) | D12: 4 | E12: 32 | K12: =(Periode!BB12*E12/40)+((F12+H12+I12)*Periode!BD12/40)+(J12*Periode!BF12/40)+(G12*Periode!BE12/40) -> 524.128 | Q12: =K12+O12+P12 -> 524.128 | R12: VrE8 | S12: VV-204-L met verklaring
B13: =Periode!B13 -> 0 | C13: =Periode!H13 -> 0 | Q13: =K13+O13+P13 -> 0
B15: =Periode!B15 -> Dennis Aarts | C15: =Periode!G15 -> 0 | I15: 32 | K15: =(Periode!BB15*E15/40)+((F15+H15+I15)*Periode!BD15/40)+(J15*Periode!BF15/40)+(G15*Periode!BE15/40) -> 548.34912 | Q15: =K15+O15+P15 -> 548.34912 | R15: 4 wekelijkse betaling | S15: 98-XH-DP Bijtelling
R16: 1 dag cursus 3 dagen leegloop
B17: =Periode!B17 -> Kay Sanders
B23: =Periode!B23 -> Frank Stouthart | C23: =Periode!G23 -> 32 (4wk) | D23: 5 | E23: 40 | K23: =(Periode!BB23*E23/40)+((F23+H23+I23)*Periode!BD23/40)+(J23*Periode!BF23/40)+(G23*Periode!BE23/40) -> 706.28 | L23: 34 | N23: =(L23*D23*2)+M23 -> 340 | O23: =((L23*2*D23)+M23)*0.28 -> 95.2 | Q23: =K23+O23+P23 -> 801.48 | S23: Vredespaleis Den Haag 34km, Lantaarnvenster R'dam 29km, Kralingseweg 179 R'dam 22 km (schrijft zelf 23km); Voorstraat Voorburg 38 km (schrijft 37km); Petrus Pauluskerk Leidschendam 31km (schrijft 33km); Kerkstraat Voorburg 31km (schrijft 33k); Koninginnegracht Den Haag 33km (schrijft 27 als hij stukje meerijdt); Tiber, den Haag 27km; Rokin 112, amsterdam 71 km (schrijft 70km); Concertgebouw 73km;
B26: =Periode!B26 -> Roy Rubeling | C26: =Periode!G26 -> 0 | D26: 4 | E26: 32 | K26: =(Periode!BB26*E26/40)+((F26+H26+I26)*Periode!BD26/40)+(J26*Periode!BF26/40)+(G26*Periode!BE26/40) -> 600 | L26: 61 | M26: =20*4 -> 80 | N26: =(L26*D26*2)+M26 -> 568 | O26: =((L26*2*D26)+M26)*0.28 -> 159.04 | Q26: =K26+O26+P26 -> 759.04 | R26: VrWAZO | S26: Akoestische maatregelen Schiphol 61km
T31: €
B33: =Periode!B33 -> Marco Govers | C33: =Periode!G33 -> 32 (4wk) | D33: 5 | E33: 40 | K33: =(Periode!BB33*E33/40)+((F33+H33+I33)*Periode!BD33/40)+(J33*Periode!BF33/40)+(G33*Periode!BE33/40) -> 775.21 | L33: 39 | N33: =(L33*D33*2)+M33 -> 390 | O33: =((L33*2*D33)+M33)*0.28 -> 109.2 | Q33: =K33+O33+P33 -> 884.41 | S33: Het Groot Kwartier 39km (schrijft 40)
B35: =Periode!B35 -> Onno de Vries | C35: =Periode!G35 -> 124 (4wk) | D35: 5 | E35: 40 | K35: =(Periode!BB35*E35/40)+((F35+H35+I35)*Periode!BD35/40)+(J35*Periode!BF35/40)+(G35*Periode!BE35/40) -> 633.355 | L35: 10 | N35: =(L35*D35*2)+M35 -> 100 | O35: =((L35*2*D35)+M35)*0.28 -> 28 | Q35: =K35+O35+P35 -> 661.355 | S35: LP4 10 km (schrijft 11km)
B39: =Periode!B39 -> Jan Levering | C39: =Periode!G39 -> 32 (4wk) | K39: =(Periode!BB39*E39/40)+((F39+H39+I39)*Periode!BD39/40)+(J39*Periode!BF39/40)+(G39*Periode!BE39/40) -> 0 | P39: 143.37 | Q39: =K39+O39+P39 -> 143.37 | R39: Aanvulling ZW € 143,37 | S39: Verklaring 1-VXV-55
B42: =Periode!B42 -> Alex van der Laan | C42: =Periode!G42 -> 32 (wk) | F42: 40 | K42: =(Periode!BB42*E42/40)+((F42+H42+I42)*Periode!BD42/40)+(J42*Periode!BF42/40)+(G42*Periode!BE42/40) -> 655.8255 | Q42: =K42+O42+P42 -> 655.8255 | R42: V40 | S42: Bijtelling 36-GNP-4
R43: VrE4 - Betalen Bewind:
R44: =K46 -> 414.45781 | S44: Bijtelling 78-RJ-BP
R45: Betalen Shafieq: | S45: Onkosten betalen op rekening Shafieq: NL65 ABNA 0128 6728 97
B46: =Periode!B46 -> Shafieq Asgarali | C46: =Periode!G46 -> 32 (4wk) | D46: 5 | E46: 33.5 | K46: =(Periode!BB46*E46/40)+((F46+H46+I46)*Periode!BD46/40)+(J46*Periode!BF46/40)+(G46*Periode!BE46/40) -> 414.45781 | P46: =(D46*Periode!AY46) -> 58.25 | Q46: =K46+O46+P46 -> 472.70781 | R46: =P46 -> 58.25 | S46: Loon betalen onder bewindvoering: NL93 ABNA 0128 6727 81
R47: Betalen loonbeslag:
B48: =Periode!B48 -> Sander van den Hoek | C48: =Periode!G48 -> 32 (wk) | D48: 5 | E48: 38 | K48: =(Periode!BB48*E48/40)+((F48+H48+I48)*Periode!BD48/40)+(J48*Periode!BF48/40)+(G48*Periode!BE48/40) -> 546.17875 | L48: 28 | N48: =(L48*D48*2)+M48 -> 280 | O48: =((L48*2*D48)+M48)*0.25 -> 70 | P48: =(D48*Periode!AY48) -> 56.8 | Q48: =K48+O48+P48+P49 -> 672.97875 | R48: =Q48-R50 -> 302.5058 | S48: Bellevoystraat Rotterdam 28km
R49: Betalen Sander: | S49: Loonbeslag Belastindienst NL89 INGB 000 000 4820
B50: =Periode!B50 -> 0 | C50: =Periode!G50 -> 0 | R50: ='WK22'!R48+O48+P48 -> 370.47295 | S50: t.n.v. S. van den Hoek 1735.64.781
R51: WoE2
B53: =Periode!B53 -> Ronald van Maanen | C53: =Periode!G53 -> 32 (4wk) | D53: 5 | E53: 40 | K53: =(Periode!BB53*E53/40)+((F53+H53+I53)*Periode!BD53/40)+(J53*Periode!BF53/40)+(G53*Periode!BE53/40) -> 733.25 | L53: 49 | N53: =(L53*D53*2)+M53 -> 490 | O53: =((L53*2*D53)+M53)*0.28 -> 137.2 | Q53: =K53+O53+P53 -> 870.45 | S53: Nijmegen gemiddelde heen/terug 49km
B54: =Periode!B75 -> 0 | C54: =Periode!H75 -> 0
B55: =Periode!B76 -> 0 | C55: =Periode!H76 -> 0
B57: =Periode!B57 -> Erik Visser | C57: =Periode!G57 -> 32 (4wk) | D57: 4 | E57: 32 | F57: 8 | K57: =(Periode!BB57*E57/40)+((F57+H57+I57)*Periode!BD57/40)+(J57*Periode!BF57/40)+(G57*Periode!BE57/40) -> 557.25992 | L57: 14 | M57: =32+48 -> 80 | N57: =(L57*D57*2)+M57 -> 192 | O57: =((L57*2*D57))*0.25+(M57*0.28) -> 50.4 | Q57: =K57+O57+P57 -> 607.65992 | R57: DiV8 - vraag erom via whatsapp | S57: Janssen de Jong OnderhoudPlus 14km
S58: wer-werk km € 0,28 (€ 0,32 naar de klant)
B59: =Periode!B59 -> 0 | C59: =Periode!G59 -> 0 | K59: =(Periode!BB59*E59/40)+((F59+H59+I59)*Periode!BD59/40)+(J59*Periode!BF59/40)+(G59*Periode!BE59/40) -> 0 | Q59: =K59+O59+P59 -> 0
R60: Betalen Bewind:
B61: =Periode!B61 -> 0 | R61: =K63 -> 463.94531
B62: =Periode!B62 -> 0 | R62: Betalen Youri:
B63: =Periode!B63 -> Youri Nouwens | C63: =Periode!G63 -> 32 (4wk) | E63: 37.5 | K63: =(Periode!BB63*E63/40)+((F63+H63+I63)*Periode!BD63/40)+(J63*Periode!BF63/40)+(G63*Periode!BE63/40) -> 463.94531 | P63: =(D63*Periode!AY63) -> 0 | Q63: =K63+O63+P63 -> 463.94531 | R63: =P63 -> 0 | S63: Bijtelling 54-GDT-8
B64: =Periode!B64 -> 0 | R64: Leegloop | S64: Loon overmaken naar Bewindvoerder: NL20 ABNA 0830 2655 89 - De Maas dienstverlening
S65: Onkosten overmaken naar Youri: NL21 INGB 0799 0333 59
B68: =Periode!B68 -> 0 | L68: 52 | N68: =(L68*D68*2)+M68 -> 0 | Q68: =K68+O68+P68 -> 0 | S68: Staalstraat Velsen-Noord 52km
...

Sheet WK24
B2: ALLEEN GEKLEURDE LETTERS EN CIJFERS INGEVEN!
P4: Overige
D5: Dagen | E5: Uren | F5: VAK | G5: ZIEK | H5: RV | I5: KV/C | J5: FD | L5: Enkel | M5: Totaal | O5: Bedrag km/ | P5: Extra | Q5: Totaal
C6: Contract | D6: ge- | E6: ge- | F6: Op- | G6: Op- | H6: Op- | I6: Door | J6: Door | K6: Netto | L6: Km woon- | M6: Km werk- | N6: Totaal | O6: brandstof | P6: Declaratie | Q6: Netto
B7: Werknemer | C7: Uren | D7: werkt | E7: werkt | F7: name | G7: name | H7: name | I7: bet. | J7: bet. | K7: bedrag | L7: werk pd | M7: werk pd | N7: Km | O7: bedrag | P7: vergoeding | Q7: Voorschot | S7: Actueel project en KM's enkele reis
B8: =Periode!B8 -> Ruben Hellemons | C8: =Periode!G8 -> 124 (4wk) | D8: 5 | E8: 40 | K8: =(Periode!BB8*E8/40)+((F8+H8+I8)*Periode!BD8/40)+(J8*Periode!BF8/40)+(G8*Periode!BE8/40) -> 721.12 | Q8: =K8+O8+P8 -> 721.12 | S8: 1-VSV-81 met verklaring
B12: =Periode!B12 -> Andre Sintenie | C12: =Periode!G12 -> 32 (4wk) | D12: 4 | E12: 32 | K12: =(Periode!BB12*E12/40)+((F12+H12+I12)*Periode!BD12/40)+(J12*Periode!BF12/40)+(G12*Periode!BE12/40) -> 524.128 | Q12: =K12+O12+P12 -> 524.128 | R12: VrE8 | S12: VV-204-L met verklaring
B13: =Periode!B13 -> 0 | C13: =Periode!H13 -> 0 | K13: =(Periode!BB13*E13/40)+((F13+G13+H13+I13)*Periode!BD13/40)+(J13*Periode!BF13/40) -> 0 | Q13: =K13+O13+P13 -> 0
P14: Tabelvoordeel: | Q14: 121.76 | R14: 4 wekelijkse betaling
B15: =Periode!B15 -> Dennis Aarts | C15: =Periode!G15 -> 0 | D15: 4 | E15: 32 | K15: =(Periode!BB15*E15/40)+((F15+H15+I15)*Periode!BD15/40)+(J15*Periode!BF15/40)+(G15*Periode!BE15/40) -> 562.928 | Q15: =(K15+O15+P15)+'WK23'!Q15+'WK22'!Q15+'WK21'!Q15 -> 1248.3644 | R15: WoE8 | S15: 98-XH-DP Bijtelling
R16: Dagloon € 114,94 bruto
B17: =Periode!B17 -> Kay Sanders | C17: =Periode!G17 -> 0 | K17: =(Periode!BB17*E17/40)+((I17)*Periode!BD17/40)+(J17*Periode!BF17/40)+(G17*Periode!BE17/40) -> 0 | L17: 69 | N17: =(L17*D17*2)+M17 -> 0 | P17: 296.04 | Q17: =K17+O17+P17 -> 296.04 | R17: Ziekte aanvulling 20% | S17: De Munt 69km
R18: Netto € 296,04
B23: =Periode!B23 -> Frank Stouthart | C23: =Periode!G23 -> 32 (4wk) | D23: 5 | E23: 39 | K23: =(Periode!BB23*E23/40)+((F23+H23+I23)*Periode!BD23/40)+(J23*Periode!BF23/40)+(G23*Periode!BE23/40) -> 688.623 | L23: 34 | M23: =-340+(6*34)+(4*36) -> 8 | N23: =(L23*D23*2)+M23 -> 348 | O23: =((L23*2*D23)+M23)*0.28 -> 97.44 | Q23: =K23+O23+P23 -> 786.063 | R23: DoE1 | S23: Beelden aan Zee 36km, Vredespaleis Den Haag 34km, Lantaarnvenster R'dam 29km, Kralingseweg 179 R'dam 22 km (schrijft zelf 23km); Voorstraat Voorburg 38 km (schrijft 37km); Petrus Pauluskerk Leidschendam 31km (schrijft 33km); Kerkstraat Voorburg 31km (schrijft 33k); Koninginnegracht Den Haag 33km (schrijft 27 als hij stukje meerijdt); Tiber, den Haag 27km; Rokin 112, amsterdam 71 km (schrijft 70km); Concertgebouw 73km;
B26: =Periode!B26 -> Roy Rubeling | C26: =Periode!G26 -> 0 | D26: 4 | E26: 32 | K26: =(Periode!BB26*E26/40)+((F26+H26+I26)*Periode!BD26/40)+(J26*Periode!BF26/40)+(G26*Periode!BE26/40) -> 600 | L26: 61 | M26: 80 | N26: =(L26*D26*2)+M26 -> 568 | O26: =((L26*2*D26)+M26)*0.28 -> 159.04 | P26: 283.62 | Q26: =K26+O26+P26 -> 1042.66 | R26: WAZO nog nabetalen 4 * 8 uur | S26: Akoestische maatregelen Schiphol 61km
R27: € 283,62 WAZO
T31: €
B33: =Periode!B33 -> Marco Govers | C33: =Periode!G33 -> 32 (4wk) | D33: 5 | E33: 38.5 | I33: 1.5 | K33: =(Periode!BB33*E33/40)+((F33+H33+I33)*Periode!BD33/40)+(J33*Periode!BF33/40)+(G33*Periode!BE33/40) -> 774.49978 | L33: 39 | N33: =(L33*D33*2)+M33 -> 390 | O33: =((L33*2*D33)+M33)*0.28 -> 109.2 | Q33: =K33+O33+P33 -> 883.69978 | R33: DoKV1,5 | S33: Het Groot Kwartier 39km (schrijft 40)
P34: Tabelvoordeel: | Q34: 13.59
B35: =Periode!B35 -> Onno de Vries | C35: =Periode!G35 -> 124 (4wk) | D35: 5 | E35: 40 | K35: =(Periode!BB35*E35/40)+((F35+H35+I35)*Periode!BD35/40)+(J35*Periode!BF35/40)+(G35*Periode!BE35/40) -> 633.355 | L35: 10 | N35: =(L35*D35*2)+M35 -> 100 | O35: =((L35*2*D35)+M35)*0.28 -> 28 | Q35: =K35+O35+P35 -> 661.355 | S35: LP4 10 km (schrijft 11km)
B39: =Periode!B39 -> Jan Levering | C39: =Periode!G39 -> 32 (4wk) | K39: =(Periode!BB39*E39/40)+((F39+H39+I39)*Periode!BD39/40)+(J39*Periode!BF39/40)+(G39*Periode!BE39/40) -> 0 | P39: 143.37 | Q39: =K39+O39+P39 -> 143.37 | R39: Aanvulling ZW € 143,37 | S39: Verklaring 1-VXV-55
B42: =Periode!B42 -> Alex van der Laan | C42: =Periode!G42 -> 32 (wk) | D42: 2 | E42: 16 | H42: 24 | K42: =(Periode!BB42*E42/40)+((F42+H42+I42)*Periode!BD42/40)+(J42*Periode!BF42/40)+(G42*Periode!BE42/40) -> 662.9953 | Q42: =K42+O42+P42 -> 662.9953 | R42: Ma t/m Wo V24 | S42: Bijtelling 36-GNP-4
R43: Betalen Bewind:
R44: =K46+Q45 -> 595.12531 | S44: Bijtelling 78-RJ-BP
P45: Tabelvoordeel: | Q45: 131.18 | R45: Betalen Shafieq: | S45: Onkosten betalen op rekening Shafieq: NL65 ABNA 0128 6728 97
B46: =Periode!B46 -> Shafieq Asgarali | C46: =Periode!G46 -> 32 (4wk) | D46: 5 | E46: 37.5 | K46: =(Periode!BB46*E46/40)+((F46+H46+I46)*Periode!BD46/40)+(J46*Periode!BF46/40)+(G46*Periode!BE46/40) -> 463.94531 | P46: =(D46*Periode!AY46) -> 58.25 | Q46: =K46+O46+P46 -> 522.19531 | R46: =P46 -> 58.25 | S46: Loon betalen onder bewindvoering: NL93 ABNA 0128 6727 81
P47: Tabelvoordeel: | Q47: 153.62 | R47: Betalen loonbeslag:
B48: =Periode!B48 -> Sander van den Hoek | C48: =Periode!G48 -> 32 (wk) | D48: 5 | E48: 38 | K48: =(Periode!BB48*E48/40)+((F48+H48+I48)*Periode!BD48/40)+(J48*Periode!BF48/40)+(G48*Periode!BE48/40) -> 546.17875 | L48: 28 | N48: =(L48*D48*2)+M48 -> 280 | O48: =((L48*2*D48)+M48)*0.25 -> 70 | P48: =(D48*Periode!AY48) -> 56.8 | Q48: =K48+O48+P48+P49 -> 672.97875 | R48: =K48+Q47 -> 699.79875 | S48: Bellevoystraat Rotterdam 28km
R49: Betalen Sander: | S49: Loonbeslag Belastindienst NL89 INGB 000 000 4820
B50: =Periode!B50 -> 0 | C50: =Periode!G50 -> 0 | R50: =O48+P48 -> 126.8 | S50: t.n.v. S. van den Hoek 1735.64.781
R51: WoE2
B53: =Periode!B53 -> Ronald van Maanen | C53: =Periode!G53 -> 32 (4wk) | D53: 5 | E53: 39.5 | K53: =(Periode!BB53*E53/40)+((F53+H53+I53)*Periode!BD53/40)+(J53*Periode!BF53/40)+(G53*Periode!BE53/40) -> 724.08438 | L53: 49 | N53: =(L53*D53*2)+M53 -> 490 | O53: =((L53*2*D53)+M53)*0.28 -> 137.2 | Q53: =K53+O53+P53 -> 861.28438 | R53: DoE0,5 | S53: Nijmegen gemiddelde heen/terug 49km
B54: =Periode!B75 -> 0 | C54: =Periode!H75 -> 0
B55: =Periode!B76 -> 0 | C55: =Periode!H76 -> 0
P56: Tabelvoordeel: | Q56: 60.63
B57: =Periode!B57 -> Erik Visser | C57: =Periode!G57 -> 32 (4wk) | D57: 4 | E57: 29 | F57: 8 | K57: =(Periode!BB57*E57/40)+((F57+H57+I57)*Periode!BD57/40)+(J57*Periode!BF57/40)+(G57*Periode!BE57/40) -> 515.22692 | L57: 14 | M57: =74+62+32 -> 168 | N57: =(L57*D57*2)+M57 -> 280 | O57: =((L57*2*D57))*0.25+(M57*0.28) -> 75.04 | P57: 60.8 | Q57: =K57+O57+P57 -> 651.06692 | R57: DiE3 WoV8 | S57: Janssen de Jong OnderhoudPlus 14km
R58: Erik heeft erom gevraagd via whatsapp | S58: wer-werk km € 0,28 (€ 0,32 naar de klant)
R59: Nabetaling km P01 t/m P05 € 60,80
R60: Betalen Bewind:
B61: =Periode!B61 -> 0 | R61: =K63+Q62 -> 587.76531
...

Sheet Periode
B2: Legenda: | D2: ALLEEN GEKLEURDE letters en cijfers ingeven, ZWART zijn formules of vaste gegevens
D3: Een Geel gemarkeertde cel betreft een uitzondering in formule, getal of eenheid | BB3: 229 dagen 40uur | BC3: 229 dagen 40 uur | BF3: 7 dagen | BG3: Opmerking
AK4: Vergoeding | AM4: Bovm. loon | AO4: Bovenmatige | BB4: Netto afspraak | BC4: Netto SL | BD4: Vak RV RVS KV | BE4: Ziekte | BF4: Feestdagen
M5: uta/niv | T5: Reservering | V5: Reservering | W5: Reservering | Y5: TSF | Z5: Vak.geld | AA5: RV | AC5: Compensatie | AD5: Compensatie | AE5: Compensatie | AH5: Penisoen | AI5: Compensatie | AM5: per dag | AO5: sal.niv | AS5: WKR | AT5: GV | AU5: WKR | AV5: GV | AW5: WKR | AX5: IK | BB5: Incl. | BC5: incl: cao verg | BD5: incl. comp: RV | BF5: kaal loon
G6: Contract | L6: Bruto | M6: bovenm. | N6: Bruto | Q6: 0.08 | T6: VAK | V6: ADV/RV | W6: RVS/RVB | Z6: Reserv. | AA6: Reserv. | AC6: BWV | AD6: ADV/RV | AE6: RVS/RVB | AH6: compensatie | AI6: duurzame | AK6: Zorgverz. | AM6: Reisuur: | AN6: 18.95 | AO6: premie p/u | AQ6: Totaal | AS6: bovenm. | AT6: cao/gereeds. | AU6: cao/gereeds. | AV6: laarzen | AW6: Kleding | AX6: wasgeld | AY6: TOTAAL | AZ6: Auto/ | BB6: bovenm verg. | BC6: reisuren | BD6: RVS, bov.wetdg
B7: Werknemer | D7: Keuzebudget | E7: Fase | F7: Pensioen | G7: Uren | H7: CAO | I7: Recht op dagen | J7: Inregeling | K7: Functie | L7: FL | M7: Bruto | N7: Totaal | P7: RG | Q7: Vgeld | T7: dagen | U7: % | V7: dagen | W7: dagen | X7: % | Y7: dagen | Z7: 0.45 | AA7: 0.45 | AC7: dagen | AD7: dagen | AE7: dagen | AF7: % | AG7: % | AH7: p/u | AI7: inzetbaarheid | AK7: p/4wk | AM7: Bedrag | AN7: per dag | AO7: 229dg | AQ7: bruto | AS7: verg. | AT7: verg. | AU7: verg. | AV7: verg. | AW7: verg. | AX7: verg. | AY7: NETTO/dg | AZ7: reiskosten | BC7: vaste afspraken
B8: Ruben Hellemons | D8: =1895.27+14.96-847.69 -> 1062.54 | E8: Fase 4 | F8: BPF UTA | G8: 124 (4wk) | H8: UTA | I8: 25v 15rv 5rvb | J8: T4.9 FL1 FN3 SN1 | K8: Assistent Uitvoerder | L8: 19.19 | N8: =L8+M8 -> 19.19 | P8: =N8+O8 -> 19.19 | T8: 25 | U8: =T8/'Grondslag bouw & infra'!$B$50 -> 0.095785441 | V8: 15 | W8: 5 | X8: =(V8+W8)/'Grondslag bouw & infra'!$B$50 -> 0.076628352 | AC8: 0 | AD8: 0 | AE8: 0 | AF8: =(AC8+AD8+AE8)/'Grondslag bouw & infra'!$B$50 -> 0 | AI8: 0.023 | AM8: =$AN$6*AN8 -> 0 | AQ8: =(P8*(AF8+AI8)+P8) -> 19.63137 | AV8: 0.68 | AW8: 1.1 | AX8: 0.48 | AY8: =SUM(AS8:AX8) -> 2.26 | AZ8: 1-VSV-81 | BB8: =657.14+15.56+48.42 -> 721.12 | BC8: =2516.24/4 -> 629.06 | BD8: =(BB8-(AY8*5))*(1-1%) -> 702.7218 | BE8: =BD8 -> 702.7218 | BF8: =BD8 -> 702.7218
B12: Andre Sintenie | D12: =149.27+75.73 -> 225 | E12: Fase 3 | F12: Stipp Plus | G12: 32 (4wk) | H12: SAVG | I12: 25v 7atv 8rvb | J12: B.02.1 Aanloopschaal 2e jr | K12: Timmerkracht 1 | L12: 14.71 | M12: 1.28 | N12: =L12+M12 -> 15.99 | P12: =N12+O12 -> 15.99 | T12: 25 | U12: =T12/'Grondslag bouw & infra'!$B$50 -> 0.095785441 | V12: 0 | W12: 0 | X12: 0 | AC12: 0 | AD12: 0 | AE12: 0 | AF12: =(AC12+AD12+AE12)/'Grondslag bouw & infra'!$B$50 -> 0 | AM12: =$AN$6*AN12 -> 0 | AW12: 1.6 | AY12: =SUM(AS12:AX12) -> 1.6 | AZ12: VV-204-L | BB12: =627.22+2.83+20+5.11 -> 655.16 | BC12: =2232.35/4 -> 558.0875 | BD12: =(BB12-(AY12*5))*(1-1%) -> 640.6884 | BE12: =BD12 -> 640.6884 | BF12: =BD12 -> 640.6884
B15: Dennis Aarts | D15: =-542.79+1051.64+223.9 -> 732.75 | E15: Fase 1-2 | F15: BPF UTA | G15: 0 | H15: UTA | I15: 25v 15rv | J15: T4.9 FL1 FN3 SN1 | K15: Assistent uitvoerder | L15: 19.19 | N15: =L15+M15 -> 19.19 | P15: =N15+O15 -> 19.19 | T15: 25 | U15: =T15/'Grondslag bouw & infra'!$B$50 -> 0.095785441 | V15: 15 | W15: 0 | X15: =(V15+W15)/'Grondslag bouw & infra'!$B$50 -> 0.057471264 | AC15: 0 | AD15: 0 | AE15: 0 | AF15: =(AC15+AD15+AE15)/'Grondslag bouw & infra'!$B$50 -> 0 | AI15: 0.023 | AM15: =$AN$6*AN15 -> 0 | AQ15: =(P15*(AF15+AI15)+P15) -> 19.63137 | AV15: 0.68 | AW15: 1.1 | AX15: 0.48 | AY15: =SUM(AS15:AX15) -> 2.26 | AZ15: 98-XH-DP | BB15: =645+10.22+48.44 -> 703.66 | BC15: =2472.26/4 -> 618.065 | BD15: =(BB15-(AY15*5))*(1-1%) -> 685.4364 | BE15: =BD15 -> 685.4364 | BF15: =BD15 -> 685.4364
H16: Schilder | I16: 25v 7rv | O16: =N16*1.16% -> 0 | AS16: 0.26
B17: Kay Sanders | E17: Fase 1-2 | F17: Stipp basis | G17: 0 | H17: Bouw | I17: 25v 20rv | J17: T4.2 FG.A | K17: Bouwvakhelper | L17: 18.95 | N17: =L17+M17 -> 18.95 | P17: =N17+O17 -> 18.95 | Q17: Inclusief | T17: 20 | V17: 0 | W17: 0 | AC17: 5 | AD17: 20 | AE17: 0 | AF17: =(AC17+AD17+AE17)/'Grondslag bouw & infra'!$B$50 -> 0.095785441 | AI17: 0.0365 | AM17: =$AN$6*AN17 -> 0 | AV17: 0.08 | AW17: 0.13 | AX17: 0.06 | AY17: =SUM(AS17:AX17) -> 0.27 | AZ17: 0.32 | BB17: =(650/4)*5 -> 812.5 | BG17: Incl. vakantiegeld en VAKANTIEDAGEN, elke week max aanvullen!
BG18: claimt geen ziek
B20: Eric Snepvangers | D20: =-130.18-265.83-60.75-70.23-104.12-60.12+13.26-312.97-106-60.7+895.55+164.7+486.09+629 -> 1017.7 | E20: Fase 3.2 | F20: BPF Bouw | G20: 32 (4wk) | H20: Bouw | I20: 25v 20rv 8rvs | J20: T4.2 FG.A | K20: Bouwvakhelper | L20: 18.95 | N20: =L20+M20 -> 18.95 | P20: =N20+O20 -> 18.95 | T20: 20 | U20: =T20/'Grondslag bouw & infra'!$B$50 -> 0.076628352 | V20: 20 | W20: 8 | X20: =(V20+W20)/'Grondslag bouw & infra'!$B$50 -> 0.10727969 | AC20: 5 | AD20: 0 | AE20: 0 | AF20: =(AC20+AD20+AE20)/'Grondslag bouw & infra'!$B$50 -> 0.019157088 | AI20: 0.0365 | AK20: ='Grondslag bouw & infra'!C31 -> 20.667692 | AM20: =$AN$6*AN20 -> 0 | AQ20: =(P20*(AF20+AI20)+P20) -> 20.004702 | AV20: nvt | AW20: 1.1 | AX20: 0.48 | AY20: =SUM(AS20:AX20) -> 1.58 | AZ20: V-699-NT | BB20: =(525+15.12+35+8.25+7.49)/32*40 -> 738.575 | BC20: =(((2298.89)/4)*5)/4 -> 718.40312 | BD20: =(BB20-(AY20*5))*(1-1%) -> 723.36825 | BE20: =BD20 -> 723.36825 | BF20: =BD20 -> 723.36825 | BG20: 32 uur per week
B23: Frank Stouthart | D23: =1131.65+679.8-114.64-1172.79+422.97-793.6+429.31+396.89-255.37 -> 724.22 | E23: Fase 3 | F23: BPF Bouw | G23: 32 (4wk) | H23: Bouw | I23: 25v 20rv 9rvs | J23: T4.2 FG.B | K23: Timmerman II | L23: 20.02 | N23: =L23+M23 -> 20.02 | P23: =N23+O23 -> 20.02 | T23: 20 | U23: =T23/'Grondslag bouw & infra'!$B$50 -> 0.076628352 | V23: 20 | W23: 9 | X23: =(V23+W23)/'Grondslag bouw & infra'!$B$50 -> 0.11111111 | AC23: 5 | AD23: 0 | AE23: 0 | AF23: =(AC23+AD23+AE23)/'Grondslag bouw & infra'!$B$50 -> 0.019157088 | AI23: 0.0365 | AK23: ='Grondslag bouw & infra'!C31 -> 20.667692 | AM23: =$AN$6*AN23 -> 0 | AQ23: =(P23*(AF23+AI23)+P23) -> 21.134255 | AT23: 0.96 | AV23: 0.68 | AW23: 1.1 | AX23: 0.48 | AY23: =SUM(AS23:AX23) -> 3.22 | AZ23: 0.32 | BB23: =535.83+12.5+6.62+20.09+20.06+10.22+17+4.55+11.22+6.94+5.16+18.2+12.32+2.11+12.21+11.25 -> 706.28 | BC23: =2688.91/4 -> 672.2275 | BD23: =(BB23-(AY23*5))*(1-1%) -> 683.2782 | BE23: =BD23 -> 683.2782 | BF23: =BD23 -> 683.2782
B26: Roy Rubeling | E26: Fase 1-2 | F26: Stipp Basis | G26: 0 | H26: Bouw | I26: 25v 20rv | J26: T4.5 Starttabel 1e halfjaar | K26: Bouwvakhelper | L26: 15.77 | N26: =L26+M26 -> 15.77 | P26: =N26+O26 -> 15.77 | Q26: Inclusief | T26: 20 | U26: =T26/'Grondslag bouw & infra'!$B$50 -> 0.076628352 | V26: 0 | W26: 0 | X26: =(V26+W26)/'Grondslag bouw & infra'!$B$50 -> 0 | AC26: 5 | AD26: 20 | AE26: 0 | AF26: =(AC26+AD26+AE26)/'Grondslag bouw & infra'!$B$50 -> 0.095785441 | AH26: =(AQ26-'Grondslag bouw & infra'!$B$46)*'Grondslag bouw & infra'!$B$43 -> 0.23420396 | AI26: 0.0365 | AM26: =$AN$6*AN26 -> 0 | AQ26: =(P26*(AF26+AI26)+P26) -> 17.856141 | AV26: 0.68 | AW26: 1.1 | AX26: 0.48 | AY26: =SUM(AS26:AX26) -> 2.26 | AZ26: 0.32 | BB26: 750 | BC26: =2549.25/4 -> 637.3125 | BD26: =(BB26-(AY26*5))*(1-1%) -> 731.313 | BE26: =BD26 -> 731.313 | BF26: =BD26 -> 731.313
B33: Marco Govers | E33: Fase 3 | F33: BPF UTA | G33: 32 (4wk) | H33: UTA | I33: 25v 15rv 10rvb | J33: T4.9 FL1 FN3 SN1 | K33: Assistent Uitvoerder | L33: 19.19 | N33: =L33+M33 -> 19.19 | P33: =N33+O33 -> 19.19 | Q33: Inclusief | T33: 20 | U33: =T33/'Grondslag bouw & infra'!$B$50 -> 0.076628352 | V33: 0 | W33: 10 | X33: =(V33+W33)/'Grondslag bouw & infra'!$B$50 -> 0.038314176 | AC33: 5 | AD33: 15 | AE33: 0 | AF33: =(AC33+AD33+AE33)/'Grondslag bouw & infra'!$B$50 -> 0.076628352 | AI33: 0.023 | AK33: ='Grondslag bouw & infra'!C31 -> 20.667692 | AM33: =$AN$6*AN33 -> 0 | AQ33: =(P33*(AF33+AI33)+P33) -> 21.101868 | AV33: 0.68 | AW33: 1.1 | AX33: 0.48 | AY33: =SUM(AS33:AX33) -> 2.26 | AZ33: 0.32 | BB33: =750+25.21 -> 775.21 | BC33: =2793.4/4 -> 698.35 | BD33: =(BB33-(AY33*5))*(1-1%) -> 756.2709 | BE33: =BD33 -> 756.2709 | BF33: =BD33 -> 756.2709
B35: Onno de Vries | D35: =262.82+141.72+12.29+40+132.47+597.84 -> 1187.14 | E35: Fase 4 | F35: BPF bouw | G35: 124 (4wk) | H35: Bouw | I35: 25v 10rv 10tsf | J35: T4.2 FG.A | K35: Bouwvakhelper | L35: 18.95 | N35: =L35+M35 -> 18.95 | P35: =N35+O35 -> 18.95 | T35: 25 | U35: =T35/'Grondslag bouw & infra'!$B$50 -> 0.095785441 | V35: 10 | W35: 0 | X35: =(V35+W35)/'Grondslag bouw & infra'!$B$50 -> 0.038314176 | Y35: 10 | Z35: =8%*0.45 -> 0.036 | AA35: =(Y35*0.4%)*0.45 -> 0.018 | AC35: 0 | AD35: 0 | AE35: 0 | AF35: =(AC35+AD35+AE35)/'Grondslag bouw & infra'!$B$50 -> 0 | AI35: 0.0365 | AM35: =$AN$6*AN35 -> 0 | AQ35: =(P35*(AF35+AI35)+P35) -> 19.641675 | AV35: 0.68 | AW35: 1.1 | AX35: 0.48 | AY35: =SUM(AS35:AX35) -> 2.26 | AZ35: 0.32 | BB35: =BC35 -> 633.355 | BC35: =2533.42/4 -> 633.355 | BD35: =(BB35-(AY35*5))*(1-1%) -> 615.83445 | BE35: =BD35 -> 615.83445 | BF35: =BD35 -> 615.83445 | BG35: TSF
B39: Jan Levering | D39: =274.46+100-33.16-194.32-139.89-110-49-44.45-770.58+838.07-55.5+362.08+110.7-470.25+506.46 -> 324.62 | E39: Fase 3 | F39: BPF UTA | G39: 32 (4wk) | H39: UTA | I39: 25v 15rv 7rvs | J39: T4.9 FL23 FN1 SN2 (104%) | K39: Intern onderhoudsmedewerker | L39: 15.77 | M39: 2.45 | N39: =L39+M39 -> 18.22 | P39: =N39+O39 -> 18.22 | T39: 20 | U39: =T39/'Grondslag bouw & infra'!$B$50 -> 0.076628352 | V39: 15 | W39: 7 | X39: =(V39+W39)/'Grondslag bouw & infra'!$B$50 -> 0.084291188 | AC39: 5 | AD39: 0 | AE39: 0 | AF39: =(AC39+AD39+AE39)/'Grondslag bouw & infra'!$B$50 -> 0.019157088 | AI39: 0.023 | AK39: ='Grondslag bouw & infra'!C31 -> 20.667692 | AM39: =$AN$6*AN39 -> 0 | AQ39: =(P39*(AF39+AI39)+P39) -> 18.988102 | AV39: 0.68 | AW39: 1.1 | AX39: 0.48 | AY39: =SUM(AS39:AX39) -> 2.26 | AZ39: 1-VXV-55 | BB39: =615+2.1+8.54+5.25+7.12+68.1 -> 706.11 | BC39: =2466.24/4 -> 616.56 | BD39: =(BB39-(AY39*5))*(1-1%) -> 687.8619 | BE39: =BD39 -> 687.8619 | BF39: =BD39 -> 687.8619 | BG39: werkt 128 uur per 4 weken
B42: Alex van der Laan | D42: =-223.64+228.7-236.63-38-79.66-126.55-166.02-103.65+567.94-55.17+503.89-116.84-82.72-54.97-132.63-54.35+926.65-149.3 -> 607.05 | E42: Fase 4 | F42: BPF UTA | G42: 32 (wk) | H42: UTA | I42: 25v 15rv | J42: T4.9 FL1 FN3 116% | K42: Assistent uitvoerder | L42: =19.19*1.16 -> 22.2604 | N42: =L42+M42 -> 22.2604 | P42: =N42+O42 -> 22.2604 | T42: 25 | U42: =T42/'Grondslag bouw & infra'!$B$50 -> 0.095785441 | V42: 15 | W42: 0 | X42: =(V42+W42)/'Grondslag bouw & infra'!$B$50 -> 0.057471264 | Z42: =8%*0.45 -> 0.036 | AC42: 0 | AD42: 0 | AE42: 0 | AF42: =(AC42+AD42+AE42)/'Grondslag bouw & infra'!$B$50 -> 0 | AI42: 0.023 | AK42: ='Grondslag bouw & infra'!C31 -> 20.667692 | AM42: =$AN$6*AN42 -> 0 | AQ42: =(P42*(AF42+AI42)+P42) -> 22.772389 | AV42: 0.68 | AW42: 1.1 | AX42: 0.48 | AY42: =SUM(AS42:AX42) -> 2.26 | AZ42: 36-GNP-4 | BB42: =BC42 -> 673.75 | BC42: =2695/4 -> 673.75 | BD42: =(BB42-(AY42*5))*(1-1%) -> 655.8255 | BE42: =BD42 -> 655.8255 | BF42: =BD42 -> 655.8255 | BG42: TSF
D44: =1-1+5.5+2.5+4.5 -> 12.5
B46: Shafieq Asgarali | D46: =537.66-(72*1.8)-(29*1.8) -> 355.86 | E46: Fase 3 | F46: Stipp Plus | G46: 32 (4wk) | H46: SAVG | I46: 25v 7atv | J46: LG.01 Aanloopschaal 1e jaar | L46: 14.71 | M46: 0.02 | N46: =L46+M46 -> 14.73 | P46: =N46+O46 -> 14.73 | T46: 25 | U46: =T46/'Grondslag bouw & infra'!$B$50 -> 0.095785441 | V46: 0 | W46: 0 | X46: =(V46+W46)/'Grondslag bouw & infra'!$B$50 -> 0 | AC46: 0 | AD46: 0 | AE46: 0 | AF46: =(AC46+AD46+AE46)/'Grondslag bouw & infra'!$B$50 -> 0 | AM46: =$AN$6*AN46 -> 0 | AS46: =(7.5*1.34) -> 10.05 | AW46: 1.6 | AY46: =SUM(AS46+AW46) -> 11.65 | AZ46: 78-RJ-BP | BB46: =BC46-(5*AY46) -> 494.875 | BC46: =2212.5/4 -> 553.125 | BD46: =BB46 -> 494.875 | BE46: =BD46 -> 494.875 | BF46: =BD46 -> 494.875 | BG46: Proforma gedraaid op 150 uur
B48: Sander van den Hoek | D48: =-64.45-203.93-62.94-262.8-98.76+429.51 -> -263.37 | E48: Fase 3 | F48: BPF UTA | G48: 32 (wk) | H48: UTA | I48: 25v 15rv | J48: T4.9 FL8 FN1 SN1 | K48: Aanvoerder beheer materieel | L48: 15.77 | N48: =L48+M48 -> 15.77 | P48: =N48+O48 -> 15.77 | Q48: Inclusief | T48: 25 | U48: =T48/'Grondslag bouw & infra'!$B$50 -> 0.095785441 | V48: 15 | W48: 0 | X48: =(V48+W48)/'Grondslag bouw & infra'!$B$50 -> 0.057471264 | AB48: 0 | AC48: 0 | AD48: 0 | AE48: 0 | AF48: =(AC48+AD48+AE48)/'Grondslag bouw & infra'!$B$50 -> 0 | AI48: 0.023 | AM48: =$AN$6*AN48 -> 0 | AQ48: =(P48*(AF48+AI48)+P48) -> 16.13271 | AS48: 9.1 | AV48: 0.68 | AW48: 1.1 | AX48: 0.48 | AY48: =SUM(AS48:AX48) -> 11.36 | AZ48: 0.25 | BB48: =BC48-(5*AY48) -> 574.925 | BC48: =2526.9/4 -> 631.725 | BD48: =BB48 -> 574.925 | BE48: =BD48 -> 574.925 | BF48: =BD48 -> 574.925
B51: Marcel van Zandwijk | E51: Fase 3 | F51: BPF UTA | G51: 32 (4wk) | H51: UTA | I51: 25v 15rv | J51: T4.9 FL1 FN4 SN1 | K51: Uitvoering | L51: 21.7 | N51: =L51+M51 -> 21.7 | P51: =N51+O51 -> 21.7 | Q51: Inclusief | T51: 20 | U51: =T51/'Grondslag bouw & infra'!$B$50 -> 0.076628352 | V51: 0 | W51: 0 | X51: =(V51+W51)/'Grondslag bouw & infra'!$B$50 -> 0 | AC51: 5 | AD51: 15 | AE51: 0 | AF51: =(AC51+AD51+AE51)/'Grondslag bouw & infra'!$B$50 -> 0.076628352 | AI51: 0.023 | AM51: =2*AN6 -> 37.9 | AN51: 2 | AV51: 0.68 | AX51: 0.48 | AY51: 0.27 | BB51: =937.5-17+5.21+7.52 -> 933.23 | BC51: =2962.53/4 -> 740.6325 | BD51: =(BB51-(AY51*5))*(1-1%) -> 922.5612 | BE51: =BD51 -> 922.5612 | BF51: =BD51 -> 922.5612 | BG51: Netto incl. vakantiegeld, -9,48 bijtelling
B53: Ronald van Maanen | D53: =91.95 -> 91.95 | E53: Fase 3 | F53: BPF bouw | G53: 32 (4wk) | H53: Bouw | I53: 25v 20rv | J53: T4.2 FG.B | K53: Timmerman II | L53: 20.02 | N53: =L53+M53 -> 20.02 | P53: =N53+O53 -> 20.02 | T53: 20 | U53: =T53/'Grondslag bouw & infra'!$B$50 -> 0.076628352 | V53: 9 | W53: 0 | X53: =(V53+W53)/'Grondslag bouw & infra'!$B$50 -> 0.034482759 | AC53: 5 | AD53: 11 | AE53: 0 | AF53: =(AC53+AD53+AE53)/'Grondslag bouw & infra'!$B$50 -> 0.061302682 | AI53: 0.0365 | AM53: =$AN$6*AN53 -> 0 | AU53: 0.96 | AV53: 0.68 | AW53: 1.1 | AX53: 0.48 | AY53: =SUM(AS53:AX53) -> 3.22 | AZ53: 0.32 | BB53: =605.03+25.1+9.25+17.2+15+3.5+25+11.21+21.96 -> 733.25 | BC53: =2750.23/4 -> 687.5575 | BD53: =(BB53-(AY53*5))*(1-1%) -> 709.9785 | BE53: =BD53 -> 709.9785 | BF53: =BD53 -> 709.9785
AI56: Reserveren
B57: Erik Visser | D57: =1330.2-74-128-112.39-149.58-82.6-111.69-120-148.42-270-139.63-20.62+1859.46-150-575+25.07+50.13-900+722.47+314.5-59.92-91.89-1440+303.2+1548.29-90.99-126.45 -> 1362.14 | E57: Fase 3 | F57: BPF UTA | G57: 32 (4wk) | H57: UTA | I57: 25v 15rv 3rvb | J57: T4.9 FL15 FN1 SN2 104% | K57: Werkterminal administrateur | L57: =15.77 -> 15.77 | M57: 1.04 | N57: =L57*M57 -> 16.4008 | P57: =N57+O57 -> 16.4008 | T57: 25 | U57: =T57/'Grondslag bouw & infra'!$B$50 -> 0.095785441 | V57: 15 | W57: 3 | X57: =(V57+W57)/'Grondslag bouw & infra'!$B$50 -> 0.068965517 | AC57: 0 | AD57: 0 | AE57: 0 | AF57: =(AC57+AD57+AE57)/'Grondslag bouw & infra'!$B$50 -> 0 | AI57: 0.023 | AM57: =$AN$6*AN57 -> 0 | AQ57: =(P57*(AF57+AI57)+P57) -> 16.778018 | AS57: =(0.08+0.12+0.06)*8 -> 2.08 | AY57: =SUM(AS57:AX57) -> 2.08 | AZ57: 0.25 | BB57: =BC57 -> 560.44 | BC57: =2241.76/4 -> 560.44 | BD57: =(BB57-(AY57*5))*(1-1%) -> 544.5396 | BE57: =BD57 -> 544.5396 | BF57: =BD57 -> 544.5396
B60: Dirk Nouwens | D60: =20.15+215.8 -> 235.95 | E60: Fase 1-2 | F60: AOW | G60: 0 | H60: UTA | I60: 25v 15rv 9rvs | J60: T4.11 starttabel 2e halfjaar | K60: Aanvoerder | L60: 15.24 | N60: =L60+M60 -> 15.24 | P60: =N60+O60 -> 15.24 | Q60: Inclusief | T60: 25 | U60: =T60/'Grondslag bouw & infra'!$B$50 -> 0.095785441 | V60: 15 | W60: 9 | X60: =(V60+W60)/'Grondslag bouw & infra'!$B$50 -> 0.091954023 | AB60: 0 | AC60: 0 | AD60: 0 | AE60: 0 | AF60: =(AC60+AD60+AE60)/'Grondslag bouw & infra'!$B$50 -> 0 | AI60: 0.023 | AM60: =$AN$6*AN60 -> 0 | AQ60: =(P60*(AF60+AI60)+P60) -> 15.59052 | AV60: 0.68 | AW60: 1.1 | AX60: 0.48 | AY60: =SUM(AS60:AX60) -> 2.26 | AZ60: 0.25 | BB60: =677.84 -> 677.84 | BC60: =2606.28/4 -> 651.57 | BD60: =(BB60-(AY60*5))*(1-1%) -> 659.8746 | BE60: =BD60 -> 659.8746 | BF60: =BD60 -> 659.8746
B63: Youri Nouwens | D63: =298.99+304.75-898+294.26-438.63+1541-1014.88 -> 87.49 | E63: Fase 3 | F63: Stipp Plus | G63: 32 (4wk) | H63: SAVG | I63: 25v 7atv | J63: B.01.1 Aanloop 2e jaar | K63: Hulpkracht | L63: 14.71 | M63: 0.02 | N63: =L63+M63 -> 14.73 | P63: =N63+O63 -> 14.73 | T63: 25 | U63: =T63/'Grondslag bouw & infra'!$B$50 -> 0.095785441 | V63: 0 | W63: 0 | X63: =(V63+W63)/'Grondslag bouw & infra'!$B$50 -> 0 | AC63: 0 | AD63: 0 | AE63: 0 | AF63: =(AC63+AD63+AE63)/'Grondslag bouw & infra'!$B$50 -> 0 | AM63: =$AN$6*AN63 -> 0 | AS63: =7.5*1.34 -> 10.05 | AW63: 1.6 | AY63: =SUM(AS63+AW63) -> 11.65 | AZ63: 54-GDT-8 | BB63: =BC63-(5*AY63) -> 494.875 | BC63: =2212.5/4 -> 553.125 | BD63: =BB63 -> 494.875 | BE63: =BD63 -> 494.875 | BF63: =BD63 -> 494.875
D69: =(163-150)+(144-135)-22 -> 0
B70: Marco Booij | D70: =1185-102.84-612.6-18.59-326.6+819-943.37 -> 0 | E70: Fase 3.2 | F70: Stipp Plus | G70: 32 (4wk) | H70: Schilder | I70: 25v 7atv | J70: S.02.1 LG 02.02 | K70: Schilder 1 | L70: 18.93 | N70: =L70+M70 -> 18.93 | P70: =N70+O70 -> 18.93 | T70: 20 | U70: =T70/'Grondslag bouw & infra'!$B$50 -> 0.076628352 | V70: 0 | W70: 0 | X70: =(V70+W70)/'Grondslag bouw & infra'!$B$50 -> 0 | AC70: 5 | AD70: 0 | AE70: 0 | AF70: =(AC70+AD70+AE70)/'Grondslag bouw & infra'!$B$50 -> 0.019157088 | AM70: =$AN$6*AN70 -> 0 | AW70: 1.6 | AY70: =SUM(AS70:AX70) -> 1.6 | AZ70: 52-LN-BT | BB70: =660+10.4+15.2+26.52+8.1 -> 720.22 | BD70: =(BB70-(AY70*5))*(1-1%) -> 705.0978 | BF70: =BD70 -> 705.0978
B74: Kevin Schuiling | D74: =162.2 -> 162.2 | E74: Fase 3 | F74: BPF Bouw | G74: 32 (4wk) | H74: Bouw | I74: 25v 20rv | J74: T4.2 FG.A | K74: Bouwvakhelper | L74: 18.95 | N74: =L74+M74 -> 18.95 | P74: =N74+O74 -> 18.95 | Q74: Inclusief | T74: 25 | U74: =T74/'Grondslag bouw & infra'!$B$50 -> 0.095785441 | V74: 20 | W74: 0 | X74: =(V74+W74)/'Grondslag bouw & infra'!$B$50 -> 0.076628352 | AC74: 0 | AD74: 0 | AE74: 0 | AF74: =(AC74+AD74+AE74)/'Grondslag bouw & infra'!$B$50 -> 0 | AI74: 0.0365 | AM74: 0 | AQ74: =(P74*(AF74+AI74)+P74) -> 19.641675 | AV74: 0.68 | AW74: 1.1 | AX74: 0.48 | AY74: =SUM(AS74:AX74) -> 2.26 | AZ74: 0.32 | BB74: =600 -> 600 | BC74: =2674.32/4 -> 668.58 | BD74: =(BB74-(AY74*5))*(1-1%) -> 582.813 | BE74: =BD74 -> 582.813 | BF74: =BD74 -> 582.813
B77: Steven Lamers | D77: =217.02 -> 217.02 | E77: Fase 3 | F77: BPF Bouw | G77: 32 (4wk) | H77: Bouw | I77: 25v 20rv | J77: T4.2 FG.A | K77: Bouwvakhelper | L77: 18.95 | N77: =L77+M77 -> 18.95 | P77: =N77+O77 -> 18.95 | Q77: Inclusief | T77: 25 | U77: =T77/'Grondslag bouw & infra'!$B$50 -> 0.095785441 | V77: 20 | W77: 0 | X77: =(V77+W77)/'Grondslag bouw & infra'!$B$50 -> 0.076628352 | AC77: 0 | AD77: 0 | AE77: 0 | AF77: =(AC77+AD77+AE77)/'Grondslag bouw & infra'!$B$50 -> 0 | AI77: 0.0365 | AM77: 0 | AQ77: =(P77*(AF77+AI77)+P77) -> 19.641675 | AV77: 0.68 | AW77: 1.1 | AX77: 0.48 | AY77: =SUM(AS77:AX77) -> 2.26 | AZ77: 82-VZJ-2 | BB77: =BC77 -> 663.32 | BC77: =2653.28/4 -> 663.32 | BD77: =(BB77-(AY77*5))*(1-1%) -> 645.4998 | BE77: =BD77 -> 645.4998 | BF77: =BD77 -> 645.4998
B80: Leo van Doorn | D80: 1122.03 | E80: Fase 1 -2 | F80: BPF UTA | G80: 0 | H80: UTA | I80: 25v 15rv 5rvS | J80: T4.9 FL1 FN3 SN1 | K80: Assistent Uitvoerder | L80: 19.19 | M80: 0.51 | N80: =L80+M80 -> 19.7 | P80: =N80+O80 -> 19.7 | T80: 20 | U80: =T80/'Grondslag bouw & infra'!$B$50 -> 0.076628352 | V80: 8 | W80: 0 | X80: =(V80+W80)/'Grondslag bouw & infra'!$B$50 -> 0.030651341 | AC80: 5 | AD80: 7 | AE80: 5 | AF80: =(AC80+AD80+AE80)/'Grondslag bouw & infra'!$B$50 -> 0.0651341 | AI80: 0.023 | AM80: 0 | AV80: 0.68 | AW80: 1.1 | AX80: 0.48 | AY80: =SUM(AS80:AX80) -> 2.26 | AZ80: 0.32 | BB80: =700.56+11.2 -> 711.76 | BC80: =2657.58/4 -> 664.395 | BD80: =(BB80-(AY80*5))*(1-1%) -> 693.4554 | BE80: =BD80 -> 693.4554 | BF80: =BD80 -> 693.4554
B83: Tobin van de Kuil | E83: Fase 1-2 | F83: StiPP | G83: 0 | H83: Bouw | I83: 25v 20rv | J83: T4.2 FG.B | K83: Timmerman II | L83: 20.02 | N83: =L83+M83 -> 20.02 | P83: =N83+O83 -> 20.02 | Q83: Inclusief | T83: 20 | U83: =T83/'Grondslag bouw & infra'!$B$50 -> 0.076628352 | V83: 0 | W83: 0 | X83: =(V83+W83)/'Grondslag bouw & infra'!$B$50 -> 0 | AC83: 5 | AD83: 20 | AE83: 0 | AF83: =(AC83+AD83+AE83)/'Grondslag bouw & infra'!$B$50 -> 0.095785441 | AH83: =(AQ83-'Grondslag bouw & infra'!$B$46)*'Grondslag bouw & infra'!$B$43 -> 0.36500953 | AI83: 0.0365 | AM83: 0 | AQ83: =(P83*(AF83+AI83)+P83) -> 22.668355 | AU83: 0.96 | AV83: 0.68 | AW83: 1.1 | AX83: 0.48 | AY83: =SUM(AS83:AX83) -> 3.22 | AZ83: 0.32 | BB83: =BC83 -> 752.795 | BC83: =3011.18/4 -> 752.795 | BD83: =(BB83-(AY83*5))*(1-1%) -> 729.32805 | BE83: =BD83 -> 729.32805 | BF83: =BD83 -> 729.32805
B87: Carlo Peetoom | D87: =89.02-89.02 -> 0 | E87: Fase 3 | F87: BPF UTA | G87: 32 (4wk) | H87: UTA | I87: 25v 15rv | J87: T4.9 FL1 FN3 SN1 | K87: Assistent Uitvoerder | L87: 19.19 | N87: =L87+M87 -> 19.19 | P87: =N87+O87 -> 19.19 | Q87: Inclusief | T87: 20 | U87: =T87/'Grondslag bouw & infra'!$B$50 -> 0.076628352 | V87: 10 | W87: 0 | X87: =(V87+W87)/'Grondslag bouw & infra'!$B$50 -> 0.038314176 | AC87: 5 | AD87: 5 | AE87: 0 | AF87: =(AC87+AD87+AE87)/'Grondslag bouw & infra'!$B$50 -> 0.038314176 | AI87: 0.023 | AM87: =$AN$6*AN87 -> 0 | AQ87: =(P87*(AF87+AI87)+P87) -> 20.366619 | AS87: 2.4 | AV87: 0.68 | AW87: 1.1 | AX87: 0.48 | AY87: =SUM(AS87:AX87) -> 4.66 | AZ87: 0.25 | BB87: =(650+11.23+11.31)/32*40 -> 840.675 | BC87: =2786.94/4 -> 696.735 | BD87: =(BB87-(AY87*5))*(1-1%) -> 809.20125 | BE87: =BD87 -> 809.20125 | BF87: =BD87 -> 809.20125
B90: Aries Provence | E90: Fase 1-2 | F90: AOW | G90: 0 | H90: UTA | I90: 25v 15rv 11rvs | J90: T4.11 Starttabel 1st halfjaar | K90: Assistent Uitvoerder | L90: 14.98 | N90: =L90+M90 -> 14.98 | P90: =N90+O90 -> 14.98 | Q90: Inclusief | T90: 25 | U90: =T90/'Grondslag bouw & infra'!$B$50 -> 0.095785441 | V90: 15 | W90: 11 | X90: =(V90+W90)/'Grondslag bouw & infra'!$B$50 -> 0.099616858 | AC90: 0 | AD90: 0 | AE90: 0 | AF90: =(AC90+AD90+AE90)/'Grondslag bouw & infra'!$B$50 -> 0 | AH90: AOW | AI90: 0.023 | AM90: =$AN$6*AN90 -> 0 | AQ90: =(P90*(AF90+AI90)+P90) -> 15.32454 | AV90: 0.68 | AW90: 1.1 | AX90: 0.48 | AY90: =SUM(AS90:AX90) -> 2.26 | AZ90: 0.25 | BB90: =2401.38/4 -> 600.345 | BC90: =2217.18/4 -> 554.295 | BD90: =(BB90-(AY90*5))*(1-1%) -> 583.15455 | BE90: =BD90 -> 583.15455 | BF90: =BD90 -> 583.15455
BB91: =BB90-(BC90-BC91) -> 470.1375 | BC91: =1696.35/4 -> 424.0875
B92: Gregory de Graaf | E92: Fase 1-2 | F92: Stipp | G92: 0 | H92: Bouw | I92: 25v 20rv | J92: T4.5 starttabel 1st halfjaar | K92: Bouwvakhelper | L92: 15.77 | N92: =L92+M92 -> 15.77 | P92: =N92 -> 15.77 | Q92: Inclusief | T92: 20 | U92: =T92/'Grondslag bouw & infra'!$B$50 -> 0.076628352 | V92: 5 | W92: 0 | X92: =(V92+W92)/'Grondslag bouw & infra'!$B$50 -> 0.019157088 | AC92: 5 | AD92: 15 | AE92: 0 | AF92: =(AC92+AD92+AE92)/'Grondslag bouw & infra'!$B$50 -> 0.076628352 | AH92: =(AQ92-'Grondslag bouw & infra'!$B$46)*'Grondslag bouw & infra'!$B$43 -> 0.22599208 | AI92: 0.0365 | AM92: 0 | AQ92: =(P92*(AF92+AI92)+P92) -> 17.554034 | AV92: 0.68 | AW92: 1.1 | AX92: 0.48 | AY92: =SUM(AS92:AX92) -> 2.26 | AZ92: 34-LK-NH | BB92: 738 | BC92: =2517.42/4 -> 629.355 | BD92: =(BB92-(AY92*5))*(1-1%) -> 719.433 | BE92: =BD92 -> 719.433 | BF92: =BD92 -> 719.433
B95: Joey Cuperus
B99: Eric de Jong | E99: Fase 1-2 | F99: Stipp | G99: 0 | H99: UTA | I99: 25v 15rv | J99: T4.9 FL1 FN3 SN1 | K99: Assistent Uitvoerder | L99: 19.19 | N99: =L99+M99 -> 19.19 | P99: =N99+O99 -> 19.19 | Q99: Inclusief | T99: 20 | U99: =T99/'Grondslag bouw & infra'!$B$50 -> 0.076628352 | V99: 0 | W99: 0 | X99: =(V99+W99)/'Grondslag bouw & infra'!$B$50 -> 0 | AC99: 5 | AD99: 15 | AE99: 0 | AF99: =(AC99+AD99+AE99)/'Grondslag bouw & infra'!$B$50 -> 0.076628352 | AH99: =(AQ99-'Grondslag bouw & infra'!$B$46)*'Grondslag bouw & infra'!$B$44 -> 0.17313583 | AI99: 0.023 | AM99: =$AN$6*AN99 -> 0 | AQ99: =(P99*(AF99+AI99)+P99) -> 21.101868 | AV99: 0.68 | AW99: 1.1 | AX99: 0.48 | AY99: =SUM(AS99:AX99) -> 2.26 | AZ99: 0.23 | BB99: =1036.11-108.1 -> 928.01 | BC99: =2852.16/4 -> 713.04 | BD99: =(BB99-(AY99*5))*(1-1%) -> 907.5429 | BE99: =BD99 -> 907.5429 | BF99: =BD99 -> 907.5429
...

Sheet Loonstrook
B2: NIETS AAN VERANDEREN !!!
F3: Totaal | G3: Totaal | H3: Totaal | I3: Totaal | J3: Totaal
D4: Totaal | E4: Totaal | F4: uren | G4: uren | H4: uren | I4: uren | J4: uren | K4: Totaal | L4: Totaal | M4: Totaal wk 1-3 | N4: Totaal wk 4
D5: Dagen | E5: Uren | F5: VAK | G5: Ziek | H5: RV | I5: KV/C | J5: FD | K5: kilometers | L5: Extra | M5: reeds ontvangen | N5: nog te ontvangen
D6: ge- | E6: ge- | F6: Op- | G6: uren | H6: uren | I6: Door | J6: Door | K6: brandstof | L6: Decl. | M6: Netto | N6: Netto | O6: Te verrekenen | Q6: Alleen WKR telt mee; €185p/4wk
B7: Werknemer | C7: CAO | D7: werkt | E7: werkt | F7: name | I7: bet. | J7: bet. | K7: bedrag | L7: verg. overuur | M7: Voorschot | N7: Loon | O7: totaal 4 weken | P7: Opmerking | Q7: WKR vergoedingen | R7: Loonvoorschot strook
A8: 1 | B8: =Periode!B8 -> Ruben Hellemons | C8: =Periode!H8 -> UTA | D8: ='WK22'!D8+'WK21'!D8+'WK23'!D8+'WK24'!D8 -> 18 | E8: ='WK22'!E8+'WK21'!E8+'WK23'!E8+'WK24'!E8 -> 144 | F8: ='WK22'!F8+'WK21'!F8+'WK23'!F8+'WK24'!F8 -> 8 | G8: ='WK22'!G8+'WK21'!G8+'WK23'!G8+'WK24'!G8 -> 0 | H8: ='WK22'!H8+'WK21'!H8+'WK23'!H8+'WK24'!H8 -> 0 | I8: ='WK22'!I8+'WK21'!I8+'WK23'!I8+'WK24'!I8 -> 0 | J8: ='WK22'!J8+'WK21'!J8+'WK23'!J8+'WK24'!J8 -> 8 | K8: ='WK22'!N8+'WK21'!N8+'WK23'!N8+'WK24'!N8 -> 0 | L8: ='WK22'!P8+'WK21'!P8+'WK23'!P8+'WK24'!P8 -> 0 | M8: ='WK22'!Q8+'WK21'!Q8+'WK23'!Q8 -> 2156.0007 | N8: ='WK24'!Q8 -> 721.12 | O8: =M8+N8 -> 2877.1207 | Q8: =(378.99+11)+(194.1+22)+(168.21+16.5)+(175.41+16.5)+(169.29+15.4)+(152.21+19.8) -> 1339.41
A12: 2 | B12: =Periode!$B$12 -> Andre Sintenie | C12: =Periode!$H$12 -> SAVG | D12: ='WK22'!$D$12+'WK21'!$D$12+'WK23'!$D$12+'WK24'!$D$12 -> 13 | E12: ='WK22'!$E$12+'WK21'!$E$12+'WK23'!$E$12+'WK24'!$E$12 -> 104 | F12: ='WK22'!$F$12+'WK21'!$F$12+'WK23'!$F$12+'WK24'!$F$12 -> 0 | G12: ='WK22'!$G$12+'WK21'!$G$12+'WK23'!$G$12+'WK24'!$G$12 -> 7.6 | H12: ='WK22'!$H$12+'WK21'!$H$12+'WK23'!$H$12+'WK24'!$H$12 -> 0 | I12: ='WK22'!$I$12+'WK21'!$I$12+'WK23'!$I$12+'WK24'!$I$12 -> 0 | J12: ='WK22'!$J$12+'WK21'!$J$12+'WK23'!$J$12+'WK24'!$J$12 -> 8 | K12: ='WK22'!$N$12+'WK21'!$N$12+'WK23'!$N$12+'WK24'!$N$12 -> 0 | L12: ='WK22'!$P$12+'WK21'!$P$12+'WK23'!$P$12+'WK24'!$P$12 -> 0 | M12: ='WK22'!$Q$12+'WK21'!$Q$12+'WK23'!$Q$12 -> 1429.1565 | N12: ='WK24'!$Q$12 -> 524.128 | O12: =$N$12+$M$12 -> 1953.2845 | Q12: =(154.74+16)+(182.65+25.6)+(178.98+25.6)+(176.18+17.6)+(173.59+14.4)+(165.83+20.8) -> 1151.97
O14: ='WK24'!Q14 -> 121.76 | P14: Totaal:
A15: 3 | B15: =Periode!B15 -> Dennis Aarts | C15: =Periode!H15 -> UTA | D15: ='WK22'!D15+'WK21'!D15+'WK23'!D15+'WK24'!D15 -> 4 | E15: ='WK22'!E15+'WK21'!E15+'WK23'!E15+'WK24'!E15 -> 32 | F15: ='WK22'!F15+'WK21'!F15+'WK23'!F15+'WK24'!F15 -> 0 | G15: ='WK22'!G15+'WK21'!G15+'WK23'!G15+'WK24'!G15 -> 0 | H15: ='WK22'!H15+'WK21'!H15+'WK23'!H15+'WK24'!H15 -> 0 | I15: ='WK22'!I15+'WK21'!I15+'WK23'!I15+'WK24'!I15 -> 32 | J15: ='WK22'!J15+'WK21'!J15+'WK23'!J15+'WK24'!J15 -> 8 | K15: ='WK22'!N15+'WK21'!N15+'WK23'!N15+'WK24'!N15 -> 0 | L15: ='WK22'!P15+'WK21'!P15+'WK23'!P15+'WK24'!P15 -> 0 | M15: ='WK22'!Q15+'WK21'!Q15+'WK23'!Q15 -> 685.4364 | N15: ='WK24'!Q15 -> 1248.3644 | O15: =N15 -> 1248.3644 | P15: =O15+O14 -> 1370.1244 | Q15: =(13.2)+(16.5)+(15.4)+(14.3)+(12.1)+(4.4) -> 75.9 | R15: =-87.32-38.29+22.49+103.12 -> 0
A17: 4 | B17: =Periode!B17 -> Kay Sanders | C17: =Periode!H17 -> Bouw | D17: ='WK22'!D17+'WK21'!D17+'WK23'!D17+'WK24'!D17 -> 0 | E17: ='WK22'!E17+'WK21'!E17+'WK23'!E17+'WK24'!E17 -> 0 | F17: ='WK22'!F17+'WK21'!F17+'WK23'!F17+'WK24'!F17 -> 0 | G17: ='WK22'!G17+'WK21'!G17+'WK23'!G17+'WK24'!G17 -> 0 | H17: ='WK22'!H17+'WK21'!H17+'WK23'!H17+'WK24'!H17 -> 0 | I17: ='WK22'!I17+'WK21'!I17+'WK23'!I17+'WK24'!I17 -> 0 | J17: ='WK22'!J17+'WK21'!J17+'WK23'!J17+'WK24'!J17 -> 0 | K17: ='WK22'!N17+'WK21'!N17+'WK23'!N17+'WK24'!N17 -> 0 | L17: ='WK22'!P17+'WK21'!P17+'WK23'!P17+'WK24'!P17 -> 296.04 | M17: ='WK22'!Q17+'WK21'!Q17+'WK23'!Q17 -> 0 | N17: ='WK24'!Q17 -> 296.04 | O17: =M17+N17 -> 296.04
B20: =Periode!B20 -> Eric Snepvangers | C20: =Periode!H20 -> Bouw | D20: ='WK22'!$D$20+'WK21'!$D$20+'WK23'!$D$20+'WK24'!$D$20 -> 0 | E20: ='WK22'!$E$20+'WK21'!$E$20+'WK23'!$E$20+'WK24'!$E$20 -> 0 | F20: ='WK22'!$F$20+'WK21'!$F$20+'WK23'!$F$20+'WK24'!$F$20 -> 0 | G20: ='WK22'!$G$20+'WK21'!$G$20+'WK23'!$G$20+'WK24'!$G$20 -> 0 | H20: ='WK22'!$H$20+'WK21'!$H$20+'WK23'!$H$20+'WK24'!$H$20 -> 0 | I20: ='WK22'!$I$20+'WK21'!$I$20+'WK23'!$I$20+'WK24'!$I$20 -> 0 | J20: ='WK22'!$J$20+'WK21'!$J$20+'WK23'!$J$20+'WK24'!$J$20 -> 0 | K20: ='WK22'!$N$20+'WK21'!$N$20+'WK23'!$N$20+'WK24'!$N$20 -> 0 | L20: ='WK22'!$P$20+'WK21'!$P$20+'WK23'!$P$20+'WK24'!$P$20 -> 0 | M20: ='WK22'!$Q$20+'WK21'!$Q$20+'WK23'!$Q$20 -> 0 | N20: ='WK24'!$Q$20 -> 0 | O20: =M20+N20 -> 0 | P20: Vergoeding zorg € 20,67 | Q20: =(146.84+5.5)+(150.91+17.6)+(158.05+17.6)+(6.34+2.2) -> 505.04
C21: =Periode!$H$21 -> 0 | D21: ='WK22'!$D$21+'WK21'!$D$21+'WK23'!$D$21+'WK24'!$D$21 -> 0 | E21: ='WK22'!$E$21+'WK21'!$E$21+'WK23'!$E$21+'WK24'!$E$21 -> 0 | F21: ='WK22'!$F$21+'WK21'!$F$21+'WK23'!$F$21+'WK24'!$F$21 -> 0 | G21: ='WK22'!$G$21+'WK21'!$G$21+'WK23'!$G$21+'WK24'!$G$21 -> 0 | H21: ='WK22'!$H$21+'WK21'!$H$21+'WK23'!$H$21+'WK24'!$H$21 -> 0 | I21: ='WK22'!$I$21+'WK21'!$I$21+'WK23'!$I$21+'WK24'!$I$21 -> 0 | J21: ='WK22'!$J$21+'WK21'!$J$21+'WK23'!$J$21+'WK24'!$J$21 -> 0 | K21: ='WK22'!$N$21+'WK21'!$N$21+'WK23'!$N$21+'WK24'!$N$21 -> 0 | M21: ='WK22'!$Q$21+'WK21'!$Q$21+'WK23'!$Q$21 -> 0 | N21: ='WK24'!$Q$21 -> 0 | O21: =$M$21+$N$21 -> 0
C22: =Periode!H22 -> 0 | D22: ='WK22'!D22+'WK21'!D22+'WK23'!D22+'WK24'!D22 -> 0 | E22: ='WK22'!E22+'WK21'!E22+'WK23'!E22+'WK24'!E22 -> 0 | F22: ='WK22'!F22+'WK21'!F22+'WK23'!F22+'WK24'!F22 -> 0 | G22: ='WK22'!G22+'WK21'!G22+'WK23'!G22+'WK24'!G22 -> 0 | H22: ='WK22'!H22+'WK21'!H22+'WK23'!H22+'WK24'!H22 -> 0 | I22: ='WK22'!I22+'WK21'!I22+'WK23'!I22+'WK24'!I22 -> 0 | J22: ='WK22'!J22+'WK21'!J22+'WK23'!J22+'WK24'!J22 -> 0 | K22: ='WK22'!O22+'WK21'!O22+'WK23'!O22+'WK24'!O22 -> 0 | M22: ='WK22'!Q22+'WK21'!Q22+'WK23'!Q22 -> 0 | N22: ='WK24'!Q22 -> 0 | O22: =M22+N22 -> 0
A23: 5 | B23: =Periode!$B$23 -> Frank Stouthart | C23: =Periode!$H$23 -> Bouw | D23: ='WK22'!$D$23+'WK21'!$D$23+'WK23'!$D$23+'WK24'!$D$23 -> 18 | E23: ='WK22'!$E$23+'WK21'!$E$23+'WK23'!$E$23+'WK24'!$E$23 -> 141 | F23: ='WK22'!$F$23+'WK21'!$F$23+'WK23'!$F$23+'WK24'!$F$23 -> 8 | G23: ='WK22'!$G$23+'WK21'!$G$23+'WK23'!$G$23+'WK24'!$G$23 -> 0 | H23: ='WK22'!$H$23+'WK21'!$H$23+'WK23'!$H$23+'WK24'!$H$23 -> 0 | I23: ='WK22'!$I$23+'WK21'!$I$23+'WK23'!$I$23+'WK24'!$I$23 -> 0 | J23: ='WK22'!$J$23+'WK21'!$J$23+'WK23'!$J$23+'WK24'!$J$23 -> 8 | K23: ='WK22'!$N$23+'WK21'!$N$23+'WK23'!$N$23+'WK24'!$N$23 -> 1238 | L23: ='WK22'!$P$23+'WK21'!$P$23+'WK23'!$P$23+'WK24'!$P$23 -> 0 | M23: ='WK22'!$Q$23+'WK21'!$Q$23+'WK23'!$Q$23 -> 2323.5253 | N23: ='WK24'!$Q$23 -> 786.063 | O23: =$M$23+$N$23 -> 3109.5883 | P23: Vergoeding zorg € 20,67 | Q23: =(33.4+14.3)+(8.18+14.3)+(88.76+20.9)+(81.86+18.7)+(135.16+17.6)+(100.57+19.8) -> 553.53
